{"uuid": "344a5bc9-78f6-4a4d-8db5-f9ba26b5a923", "children": ["8ec409be-8396-4ca7-8df6-0a607bc1b0be"], "befores": [{"name": "setup_and_teardown", "status": "broken", "statusDetails": {"message": "selenium.common.exceptions.WebDriverException: Message: Service C:\\Users\\itzme\\.cache\\selenium\\chromedriver\\win64\\117.0.5938.149\\chromedriver.exe unexpectedly exited. Status code was: 3221225794\n\n", "trace": "  File \"C:\\Users\\itzme\\AppData\\Local\\Programs\\Python\\Python311\\Lib\\site-packages\\pluggy\\_callers.py\", line 137, in _multicall\n    teardown.throw(outcome._exception)\n  File \"C:\\Users\\itzme\\AppData\\Local\\Programs\\Python\\Python311\\Lib\\site-packages\\_pytest\\setuponly.py\", line 36, in pytest_fixture_setup\n    return (yield)\n            ^^^^^\n  File \"C:\\Users\\itzme\\AppData\\Local\\Programs\\Python\\Python311\\Lib\\site-packages\\pluggy\\_callers.py\", line 77, in _multicall\n    res = hook_impl.function(*args)\n          ^^^^^^^^^^^^^^^^^^^^^^^^^\n  File \"C:\\Users\\itzme\\AppData\\Local\\Programs\\Python\\Python311\\Lib\\site-packages\\_pytest\\fixtures.py\", line 1147, in pytest_fixture_setup\n    result = call_fixture_func(fixturefunc, request, kwargs)\n             ^^^^^^^^^^^^^^^^^^^^^^^^^^^^^^^^^^^^^^^^^^^^^^^\n  File \"C:\\Users\\itzme\\AppData\\Local\\Programs\\Python\\Python311\\Lib\\site-packages\\_pytest\\fixtures.py\", line 914, in call_fixture_func\n    fixture_result = next(generator)\n                     ^^^^^^^^^^^^^^^\n  File \"C:\\Users\\itzme\\PycharmProjects\\SeleniumHybridFramework\\tests\\conftest.py\", line 32, in setup_and_teardown\n    driver = webdriver.Chrome()\n             ^^^^^^^^^^^^^^^^^^\n  File \"C:\\Users\\itzme\\AppData\\Local\\Programs\\Python\\Python311\\Lib\\site-packages\\selenium\\webdriver\\chrome\\webdriver.py\", line 45, in __init__\n    super().__init__(\n  File \"C:\\Users\\itzme\\AppData\\Local\\Programs\\Python\\Python311\\Lib\\site-packages\\selenium\\webdriver\\chromium\\webdriver.py\", line 53, in __init__\n    self.service.start()\n  File \"C:\\Users\\itzme\\AppData\\Local\\Programs\\Python\\Python311\\Lib\\site-packages\\selenium\\webdriver\\common\\service.py\", line 102, in start\n    self.assert_process_still_running()\n  File \"C:\\Users\\itzme\\AppData\\Local\\Programs\\Python\\Python311\\Lib\\site-packages\\selenium\\webdriver\\common\\service.py\", line 115, in assert_process_still_running\n    raise WebDriverException(f\"Service {self._path} unexpectedly exited. Status code was: {return_code}\")\n"}, "start": 1696533411493, "stop": 1696533414305}], "start": 1696533411493, "stop": 1696533415086}