{"name": "test_login_with_valid_credentials[soumya@gmail.com-soumya123]", "status": "broken", "statusDetails": {"message": "selenium.common.exceptions.WebDriverException: Message: Service C:\\Users\\itzme\\.cache\\selenium\\chromedriver\\win64\\117.0.5938.149\\chromedriver.exe unexpectedly exited. Status code was: 3221225794", "trace": "request = <SubRequest 'setup_and_teardown' for <Function test_login_with_valid_credentials[soumya@gmail.com-soumya123]>>\n\n    @pytest.fixture()\n    def setup_and_teardown(request):\n        browser = ReadConfigurations.read_configuration(\"basic info\", \"browser\")\n        global driver\n        driver = None\n        if browser.__eq__(\"chrome\"):\n>           driver = webdriver.Chrome()\n\ntests\\conftest.py:32: \n_ _ _ _ _ _ _ _ _ _ _ _ _ _ _ _ _ _ _ _ _ _ _ _ _ _ _ _ _ _ _ _ _ _ _ _ _ _ _ _\n..\\..\\AppData\\Local\\Programs\\Python\\Python311\\Lib\\site-packages\\selenium\\webdriver\\chrome\\webdriver.py:45: in __init__\n    super().__init__(\n..\\..\\AppData\\Local\\Programs\\Python\\Python311\\Lib\\site-packages\\selenium\\webdriver\\chromium\\webdriver.py:53: in __init__\n    self.service.start()\n..\\..\\AppData\\Local\\Programs\\Python\\Python311\\Lib\\site-packages\\selenium\\webdriver\\common\\service.py:102: in start\n    self.assert_process_still_running()\n_ _ _ _ _ _ _ _ _ _ _ _ _ _ _ _ _ _ _ _ _ _ _ _ _ _ _ _ _ _ _ _ _ _ _ _ _ _ _ _\n\nself = <selenium.webdriver.chrome.service.Service object at 0x000001DA43B76290>\n\n    def assert_process_still_running(self) -> None:\n        \"\"\"Check if the underlying process is still running.\"\"\"\n        return_code = self.process.poll()\n        if return_code:\n>           raise WebDriverException(f\"Service {self._path} unexpectedly exited. Status code was: {return_code}\")\nE           selenium.common.exceptions.WebDriverException: Message: Service C:\\Users\\itzme\\.cache\\selenium\\chromedriver\\win64\\117.0.5938.149\\chromedriver.exe unexpectedly exited. Status code was: 3221225794\n\n..\\..\\AppData\\Local\\Programs\\Python\\Python311\\Lib\\site-packages\\selenium\\webdriver\\common\\service.py:115: WebDriverException"}, "parameters": [{"name": "email_address", "value": "'soumya@gmail.com'"}, {"name": "password", "value": "'soumya123'"}], "start": 1696533411492, "stop": 1696533411492, "uuid": "8ec409be-8396-4ca7-8df6-0a607bc1b0be", "testCaseId": "4bc229b8c9bfad4701f861e666d3befe", "fullName": "tests.test_Login.TestLogin#test_login_with_valid_credentials"}